<?xml version="1.0" ?>
<!-- =================================================================================== -->
<!-- |    This document was autogenerated by xacro from yellow_spot.urdf.xacro         | -->
<!-- |    EDITING THIS FILE BY HAND IS NOT RECOMMENDED                                 | -->
<!-- =================================================================================== -->
<robot name="spot">
  <material name="orange">
    <color rgba="1.0 0.5 0.0 1"/>
  </material>
  <material name="yellow">
    <color rgba="1.0 1.0 0.0 1"/>
  </material>
  <material name="black">
    <color rgba="0.1 0.1 0.1 1"/>
  </material>
  <material name="grey">
    <color rgba="0.6 0.6 0.6 1"/>
  </material>
  <!-- Left Leg: prefix is front or rear -->
  <!--   <xacro:macro name="LeftLeg" params="prefix reflect">
    <link name="${prefix}_Left_Leg">
        <visual>
            <geometry>
                <box size="${leglen} 0.1 0.2"/>
            </geometry>
            <origin xyz="0 0 -${leglen/2}" rpy="0 ${pi/2} 0"/>
            <material name="white"/>
        </visual>
        <collision>
            <geometry>
                <box size="${leglen} 0.1 0.2"/>
            </geometry>
            <origin xyz="0 0 -${leglen/2}" rpy="0 ${pi/2} 0"/>
        </collision>
        <xacro:default_inertial mass="10"/>
    </link>

    <joint name="base_to_${prefix}_leg" type="fixed">
        <parent link="base_link"/>
        <child link="${prefix}_leg"/>
        <origin xyz="0 ${reflect*(width+.02)} 0.25" />
    </joint>
</xacro:macro> -->
  <!-- <xacro:include filename="$(find mini_ros)/urdf/accessories.urdf.xacro" /> -->
  <!-- Robot description -->
  <!-- STATIC Links -->
  <link name="base_link"/>
  <link name="base_inertia">
    <visual>
      <origin rpy="0 0 -1.5707963267948966" xyz="0 0 0"/>
      <geometry>
        <mesh filename="package://mini_ros/yellow_stl/MAINBODY.stl" scale="0.001 0.001 0.001"/>
      </geometry>
      <material name="yellow"/>
    </visual>
    <collision>
      <origin rpy="0 0 -1.5707963267948966" xyz="0 0 0"/>
      <geometry>
        <box size="0.114 0.232 0.145"/>
      </geometry>
    </collision>
    <inertial>
      <mass value="0.6"/>
      <origin rpy="0 0 0" xyz="0 0 0"/>
      <!-- Inertial Axes -->
      <inertia ixx="0.0037424499999999996" ixy="0" ixz="0" iyx="0" iyy="0.0017010499999999997" iyz="0" izx="0" izy="0" izz="0.0033410000000000002"/>
    </inertial>
  </link>
  <gazebo reference="base_inertia">
    <material>Gazebo/Yellow</material>
  </gazebo>
  <!-- mm to m -->
  <!-- BATTERY -->
  <!-- <xacro:mesh_link name="battery"
              origin_rpy="0 0 ${pi/2}" origin_xyz="-0.15 0.035 -0.022"
              i_rpy="0 0 0" i_xyz="0 0 0"
              mass="0.4"
              c_xyz="0 0 0"
              length="0.048"
              width="0.145"
              height="0.026"
              matname="black"
              meshfile="package://mini_ros/stl/OpenQuadruped/Battery.stl"
              meshscale="1 1 1" /> m to mm -->
  <link name="chassis_left">
    <visual>
      <origin rpy="0 0 -1.5707963267948966" xyz="0 -0.052 0"/>
      <geometry>
        <mesh filename="package://mini_ros/yellow_stl/platform_left_side_v2_rescaled.stl" scale="0.001 0.001 0.001"/>
      </geometry>
      <material name="black"/>
    </visual>
    <collision>
      <origin rpy="0 0 -1.5707963267948966" xyz="0 0 0"/>
      <geometry>
        <box size="0.0135 0.1687 0.0414"/>
      </geometry>
    </collision>
    <inertial>
      <mass value="0.024"/>
      <origin rpy="0 0 0" xyz="0 0 0"/>
      <!-- Inertial Axes -->
      <inertia ixx="6.03473e-05" ixy="0" ixz="0" iyx="0" iyy="3.7924199999999996e-06" iyz="0" izx="0" izy="0" izz="5.7283879999999994e-05"/>
    </inertial>
  </link>
  <gazebo reference="chassis_left">
    <material>Gazebo/Black</material>
  </gazebo>
  <!-- mm to m -->
  <link name="chassis_right">
    <visual>
      <origin rpy="0 0 -1.5707963267948966" xyz="0 0.052 0"/>
      <geometry>
        <mesh filename="package://mini_ros/yellow_stl/platform_right_side_v2_rescaled.stl" scale="0.001 0.001 0.001"/>
      </geometry>
      <material name="black"/>
    </visual>
    <collision>
      <origin rpy="0 0 -1.5707963267948966" xyz="0 0 0"/>
      <geometry>
        <box size="0.0135 0.1687 0.0414"/>
      </geometry>
    </collision>
    <inertial>
      <mass value="0.024"/>
      <origin rpy="0 0 0" xyz="0 0 0"/>
      <!-- Inertial Axes -->
      <inertia ixx="6.03473e-05" ixy="0" ixz="0" iyx="0" iyy="3.7924199999999996e-06" iyz="0" izx="0" izy="0" izz="5.7283879999999994e-05"/>
    </inertial>
  </link>
  <gazebo reference="chassis_right">
    <material>Gazebo/Black</material>
  </gazebo>
  <!-- mm to m -->
  <link name="front">
    <visual>
      <origin rpy="0 0 -1.5707963267948966" xyz="0 0 0"/>
      <geometry>
        <mesh filename="package://mini_ros/yellow_stl/front_cover_v2.stl" scale="0.001 0.001 0.001"/>
      </geometry>
      <material name="yellow"/>
    </visual>
    <collision>
      <origin rpy="0 0 -1.5707963267948966" xyz="0.16 0 0.006"/>
      <geometry>
        <box size="0.116 0.127 0.103"/>
      </geometry>
    </collision>
    <inertial>
      <mass value="0.153"/>
      <origin rpy="0 0 0" xyz="0 0 0"/>
      <!-- Inertial Axes -->
      <inertia ixx="0.0003409094999999999" ixy="0" ixz="0" iyx="0" iyy="0.00030682874999999997" iyz="0" izx="0" izy="0" izz="0.00037720875"/>
    </inertial>
  </link>
  <gazebo reference="front">
    <material>Gazebo/Yellow</material>
  </gazebo>
  <!-- mm to m -->
  <link name="back">
    <visual>
      <origin rpy="0 0 -1.5707963267948966" xyz="0 0 0"/>
      <geometry>
        <mesh filename="package://mini_ros/yellow_stl/back_cover_v2.stl" scale="0.001 0.001 0.001"/>
      </geometry>
      <material name="yellow"/>
    </visual>
    <collision>
      <origin rpy="0 0 -1.5707963267948966" xyz="-0.16 0 0.006"/>
      <geometry>
        <box size="0.114 0.117 0.091"/>
      </geometry>
    </collision>
    <inertial>
      <mass value="0.116"/>
      <origin rpy="0 0 0" xyz="0 0 0"/>
      <!-- Inertial Axes -->
      <inertia ixx="0.00021237666666666674" ixy="0" ixz="0" iyx="0" iyy="0.00020567766666666667" iyz="0" izx="0" izy="0" izz="0.00025795500000000003"/>
    </inertial>
  </link>
  <gazebo reference="back">
    <material>Gazebo/Yellow</material>
  </gazebo>
  <!-- mm to m -->
  <link name="front_bracket">
    <visual>
      <origin rpy="0 0 -1.5707963267948966" xyz="0 0 0"/>
      <geometry>
        <mesh filename="package://mini_ros/yellow_stl/front_plate_v2.stl" scale="0.001 0.001 0.001"/>
      </geometry>
      <material name="black"/>
    </visual>
    <collision>
      <origin rpy="0 0 -1.5707963267948966" xyz="0.1 0 0"/>
      <geometry>
        <box size="0.11 0.103 0.092"/>
      </geometry>
    </collision>
    <inertial>
      <mass value="0.14"/>
      <origin rpy="0 0 0" xyz="0 0 0"/>
      <!-- Inertial Axes -->
      <inertia ixx="0.00022251833333333335" ixy="0" ixz="0" iyx="0" iyy="0.00023991333333333337" iyz="0" izx="0" izy="0" izz="0.00026493833333333336"/>
    </inertial>
  </link>
  <gazebo reference="front_bracket">
    <material>Gazebo/Black</material>
  </gazebo>
  <!-- mm to m -->
  <link name="back_bracket">
    <visual>
      <origin rpy="0 0 -1.5707963267948966" xyz="0 0 0"/>
      <geometry>
        <mesh filename="package://mini_ros/yellow_stl/back_plate_v2.stl" scale="0.001 0.001 0.001"/>
      </geometry>
      <material name="black"/>
    </visual>
    <collision>
      <origin rpy="0 0 -1.5707963267948966" xyz="-0.1 0 0"/>
      <geometry>
        <box size="0.11 0.104 0.092"/>
      </geometry>
    </collision>
    <inertial>
      <mass value="0.153"/>
      <origin rpy="0 0 0" xyz="0 0 0"/>
      <!-- Inertial Axes -->
      <inertia ixx="0.00024581999999999995" ixy="0" ixz="0" iyx="0" iyy="0.000262191" iyz="0" izx="0" izy="0" izz="0.000292179"/>
    </inertial>
  </link>
  <gazebo reference="back_bracket">
    <material>Gazebo/Black</material>
  </gazebo>
  <!-- mm to m -->
  <link name="front_left_hip">
    <visual>
      <origin rpy="0 0 -1.5707963267948966" xyz="0 0 0"/>
      <geometry>
        <mesh filename="package://mini_ros/yellow_stl/LEFT_HIP.stl" scale="0.001 0.001 0.001"/>
      </geometry>
      <material name="black"/>
    </visual>
    <collision>
      <origin rpy="0 0 -1.5707963267948966" xyz="0.015 0.01 -0.01"/>
      <geometry>
        <box size="0.05 0.072 0.072"/>
      </geometry>
    </collision>
    <inertial>
      <mass value="0.209"/>
      <origin rpy="0 0 0" xyz="0 0.075 0"/>
      <!-- Inertial Axes -->
      <inertia ixx="0.00018057599999999997" ixy="0" ixz="0" iyx="0" iyy="0.00013382966666666666" iyz="0" izx="0" izy="0" izz="0.00013382966666666666"/>
    </inertial>
  </link>
  <gazebo reference="front_left_hip">
    <material>Gazebo/Black</material>
  </gazebo>
  <joint name="motor_front_left_hip" type="revolute">
    <axis xyz="1 0 0"/>
    <origin rpy="0 0 0" xyz="0.181 0.038 0.03"/>
    <parent link="front_bracket"/>
    <child link="front_left_hip"/>
    <limit effort="4.0" lower="-1.04" upper="1.04" velocity="4.0"/>
    <joint_properties damping="0.0" friction="0.0"/>
  </joint>
  <link name="front_left_upper_leg">
    <visual>
      <origin rpy="0 0 -1.5707963267948966" xyz="0 0 0"/>
      <geometry>
        <mesh filename="package://mini_ros/yellow_stl/LEFT_UPPER_LEG.stl" scale="0.001 0.001 0.001"/>
      </geometry>
      <material name="black"/>
    </visual>
    <collision>
      <origin rpy="0 0 -1.5707963267948966" xyz="0 0.02 -0.05"/>
      <geometry>
        <box size="0.081 0.068 0.169"/>
      </geometry>
    </collision>
    <inertial>
      <mass value="0.268"/>
      <origin rpy="0 0 0" xyz="-0.005 0.0175 -0.055"/>
      <!-- Inertial Axes -->
      <inertia ixx="0.0007411316666666668" ixy="0" ixz="0" iyx="0" iyy="0.0007843913333333333" iyz="0" izx="0" izy="0" izz="0.00024979833333333334"/>
    </inertial>
  </link>
  <gazebo reference="front_left_upper_leg">
    <material>Gazebo/Black</material>
  </gazebo>
  <joint name="motor_front_left_upper_leg" type="revolute">
    <axis xyz="0 1 0"/>
    <origin rpy="0 0 0" xyz="-0.056999999999999995 0.030000000000000006 -0.012"/>
    <parent link="front_left_hip"/>
    <child link="front_left_upper_leg"/>
    <limit effort="4.0" lower="-1.5707963267948966" upper="2.59" velocity="4.0"/>
    <joint_properties damping="0.0" friction="0.0"/>
  </joint>
  <link name="front_left_lower_leg">
    <visual>
      <origin rpy="0 0 -1.5707963267948966" xyz="0 0 0"/>
      <geometry>
        <mesh filename="package://mini_ros/yellow_stl/LEFT_LOWER_LEG.stl" scale="0.001 0.001 0.001"/>
      </geometry>
      <material name="black"/>
    </visual>
    <collision>
      <origin rpy="0 0 -1.5707963267948966" xyz="0 0 -0.06"/>
      <geometry>
        <box size="0.022 0.034 0.155"/>
      </geometry>
    </collision>
    <inertial>
      <mass value="0.036"/>
      <origin rpy="0 0 0" xyz="-0.01 0 -0.06"/>
      <!-- Inertial Axes -->
      <inertia ixx="7.5543e-05" ixy="0" ixz="0" iyx="0" iyy="7.352699999999999e-05" iyz="0" izx="0" izy="0" izz="4.9199999999999995e-06"/>
    </inertial>
  </link>
  <gazebo reference="front_left_lower_leg">
    <material>Gazebo/Black</material>
  </gazebo>
  <joint name="motor_front_left_lower_leg" type="revolute">
    <axis xyz="0 1 0"/>
    <origin rpy="0 0 0" xyz="0.0 0.028499999999999998 -0.11900000000000001"/>
    <parent link="front_left_upper_leg"/>
    <child link="front_left_lower_leg"/>
    <limit effort="4.0" lower="-2.9" upper="1.5707963267948966" velocity="4.0"/>
    <joint_properties damping="0.0" friction="0.0"/>
  </joint>
  <link name="front_left_foot">
    <visual>
      <origin rpy="0 0 -1.5707963267948966" xyz="0 0 0"/>
      <geometry>
        <mesh filename="package://mini_ros/yellow_stl/FOOT.stl" scale="0.001 0.001 0.001"/>
      </geometry>
      <material name="yellow"/>
    </visual>
    <collision>
      <origin rpy="0 0 -1.5707963267948966" xyz="-0.247 -0.068 0.18"/>
      <geometry>
        <mesh filename="package://mini_ros/yellow_stl/FOOT.stl" scale="0.001 0.001 0.001"/>
      </geometry>
      <contact_coefficients mu="10.1"/>
    </collision>
    <inertial>
      <mass value="0.009"/>
      <origin rpy="0 0 0" xyz="0 0 0"/>
      <!-- Inertial Axes -->
      <inertia ixx="1.74e-06" ixy="0" ixz="0" iyx="0" iyy="1.6927499999999998e-06" iyz="0" izx="0" izy="0" izz="1.4887499999999997e-06"/>
    </inertial>
  </link>
  <gazebo reference="front_left_foot">
    <kp>1000000.0</kp>
    <kd>1.0</kd>
    <mu1>0.8</mu1>
    <mu2>0.8</mu2>
    <maxVel>0.0</maxVel>
    <minDepth>0.001</minDepth>
    <material>Gazebo/Yellow</material>
  </gazebo>
  <joint name="front_left_leg_foot" type="fixed">
    <origin rpy="0 0 0" xyz="-0.0030000000000000027 0 -0.127"/>
    <parent link="front_left_lower_leg"/>
    <child link="front_left_foot"/>
  </joint>
  <link name="back_left_hip">
    <visual>
      <origin rpy="0 0 -1.5707963267948966" xyz="0 0 0"/>
      <geometry>
        <mesh filename="package://mini_ros/yellow_stl/LEFT_HIP.stl" scale="0.001 0.001 0.001"/>
      </geometry>
      <material name="black"/>
    </visual>
    <collision>
      <origin rpy="0 0 -1.5707963267948966" xyz="0.015 0.01 -0.01"/>
      <geometry>
        <box size="0.05 0.072 0.072"/>
      </geometry>
    </collision>
    <inertial>
      <mass value="0.209"/>
      <origin rpy="0 0 0" xyz="0 0.075 0"/>
      <!-- Inertial Axes -->
      <inertia ixx="0.00018057599999999997" ixy="0" ixz="0" iyx="0" iyy="0.00013382966666666666" iyz="0" izx="0" izy="0" izz="0.00013382966666666666"/>
    </inertial>
  </link>
  <gazebo reference="back_left_hip">
    <material>Gazebo/Black</material>
  </gazebo>
  <joint name="motor_back_left_hip" type="revolute">
    <axis xyz="1 0 0"/>
    <origin rpy="0 0 0" xyz="-0.089 0.038 0.03"/>
    <parent link="back_bracket"/>
    <child link="back_left_hip"/>
    <limit effort="4.0" lower="-1.04" upper="1.04" velocity="4.0"/>
    <joint_properties damping="0.0" friction="0.0"/>
  </joint>
  <link name="back_left_upper_leg">
    <visual>
      <origin rpy="0 0 -1.5707963267948966" xyz="0 0 0"/>
      <geometry>
        <mesh filename="package://mini_ros/yellow_stl/LEFT_UPPER_LEG.stl" scale="0.001 0.001 0.001"/>
      </geometry>
      <material name="black"/>
    </visual>
    <collision>
      <origin rpy="0 0 -1.5707963267948966" xyz="0 0.02 -0.05"/>
      <geometry>
        <box size="0.081 0.068 0.169"/>
      </geometry>
    </collision>
    <inertial>
      <mass value="0.268"/>
      <origin rpy="0 0 0" xyz="-0.005 0.0175 -0.055"/>
      <!-- Inertial Axes -->
      <inertia ixx="0.0007411316666666668" ixy="0" ixz="0" iyx="0" iyy="0.0007843913333333333" iyz="0" izx="0" izy="0" izz="0.00024979833333333334"/>
    </inertial>
  </link>
  <gazebo reference="back_left_upper_leg">
    <material>Gazebo/Black</material>
  </gazebo>
  <joint name="motor_back_left_upper_leg" type="revolute">
    <axis xyz="0 1 0"/>
    <origin rpy="0 0 0" xyz="-0.056999999999999995 0.030000000000000006 -0.012"/>
    <parent link="back_left_hip"/>
    <child link="back_left_upper_leg"/>
    <limit effort="4.0" lower="-1.5707963267948966" upper="2.59" velocity="4.0"/>
    <joint_properties damping="0.0" friction="0.0"/>
  </joint>
  <link name="back_left_lower_leg">
    <visual>
      <origin rpy="0 0 -1.5707963267948966" xyz="0 0 0"/>
      <geometry>
        <mesh filename="package://mini_ros/yellow_stl/LEFT_LOWER_LEG.stl" scale="0.001 0.001 0.001"/>
      </geometry>
      <material name="black"/>
    </visual>
    <collision>
      <origin rpy="0 0 -1.5707963267948966" xyz="0 0 -0.06"/>
      <geometry>
        <box size="0.022 0.034 0.155"/>
      </geometry>
    </collision>
    <inertial>
      <mass value="0.036"/>
      <origin rpy="0 0 0" xyz="-0.01 0 -0.06"/>
      <!-- Inertial Axes -->
      <inertia ixx="7.5543e-05" ixy="0" ixz="0" iyx="0" iyy="7.352699999999999e-05" iyz="0" izx="0" izy="0" izz="4.9199999999999995e-06"/>
    </inertial>
  </link>
  <gazebo reference="back_left_lower_leg">
    <material>Gazebo/Black</material>
  </gazebo>
  <joint name="motor_back_left_lower_leg" type="revolute">
    <axis xyz="0 1 0"/>
    <origin rpy="0 0 0" xyz="0.0 0.028499999999999998 -0.11900000000000001"/>
    <parent link="back_left_upper_leg"/>
    <child link="back_left_lower_leg"/>
    <limit effort="4.0" lower="-2.9" upper="1.5707963267948966" velocity="4.0"/>
    <joint_properties damping="0.0" friction="0.0"/>
  </joint>
  <link name="back_left_foot">
    <visual>
      <origin rpy="0 0 -1.5707963267948966" xyz="0 0 0"/>
      <geometry>
        <mesh filename="package://mini_ros/yellow_stl/FOOT.stl" scale="0.001 0.001 0.001"/>
      </geometry>
      <material name="yellow"/>
    </visual>
    <collision>
      <origin rpy="0 0 -1.5707963267948966" xyz="-0.247 -0.068 0.18"/>
      <geometry>
        <mesh filename="package://mini_ros/yellow_stl/FOOT.stl" scale="0.001 0.001 0.001"/>
      </geometry>
      <contact_coefficients mu="10.1"/>
    </collision>
    <inertial>
      <mass value="0.009"/>
      <origin rpy="0 0 0" xyz="0 0 0"/>
      <!-- Inertial Axes -->
      <inertia ixx="1.74e-06" ixy="0" ixz="0" iyx="0" iyy="1.6927499999999998e-06" iyz="0" izx="0" izy="0" izz="1.4887499999999997e-06"/>
    </inertial>
  </link>
  <gazebo reference="back_left_foot">
    <kp>1000000.0</kp>
    <kd>1.0</kd>
    <mu1>0.8</mu1>
    <mu2>0.8</mu2>
    <maxVel>0.0</maxVel>
    <minDepth>0.001</minDepth>
    <material>Gazebo/Yellow</material>
  </gazebo>
  <joint name="back_left_leg_foot" type="fixed">
    <origin rpy="0 0 0" xyz="-0.0030000000000000027 0 -0.127"/>
    <parent link="back_left_lower_leg"/>
    <child link="back_left_foot"/>
  </joint>
  <link name="front_right_hip">
    <visual>
      <origin rpy="0 0 -1.5707963267948966" xyz="0 0 0"/>
      <geometry>
        <mesh filename="package://mini_ros/yellow_stl/RIGHT_HIP.stl" scale="0.001 0.001 0.001"/>
      </geometry>
      <material name="black"/>
    </visual>
    <collision>
      <origin rpy="0 0 -1.5707963267948966" xyz="0.015 -0.01 -0.01"/>
      <geometry>
        <box size="0.05 0.072 0.072"/>
      </geometry>
    </collision>
    <inertial>
      <mass value="0.209"/>
      <origin rpy="0 0 0" xyz="0 -0.075 0"/>
      <!-- Inertial Axes -->
      <inertia ixx="0.00018057599999999997" ixy="0" ixz="0" iyx="0" iyy="0.00013382966666666666" iyz="0" izx="0" izy="0" izz="0.00013382966666666666"/>
    </inertial>
  </link>
  <gazebo reference="front_right_hip">
    <material>Gazebo/Black</material>
  </gazebo>
  <joint name="motor_front_right_hip" type="revolute">
    <axis xyz="1 0 0"/>
    <origin rpy="0 0 0" xyz="0.181 -0.038 0.03"/>
    <parent link="front_bracket"/>
    <child link="front_right_hip"/>
    <limit effort="4.0" lower="-1.04" upper="1.04" velocity="4.0"/>
    <joint_properties damping="0.0" friction="0.0"/>
  </joint>
  <link name="front_right_upper_leg">
    <visual>
      <origin rpy="0 0 -1.5707963267948966" xyz="0 0 0"/>
      <geometry>
        <mesh filename="package://mini_ros/yellow_stl/RIGHT_UPPER_LEG.stl" scale="0.001 0.001 0.001"/>
      </geometry>
      <material name="black"/>
    </visual>
    <collision>
      <origin rpy="0 0 -1.5707963267948966" xyz="0 -0.02 -0.05"/>
      <geometry>
        <box size="0.081 0.068 0.169"/>
      </geometry>
    </collision>
    <inertial>
      <mass value="0.268"/>
      <origin rpy="0 0 0" xyz="-0.005 -0.0175 -0.055"/>
      <!-- Inertial Axes -->
      <inertia ixx="0.0007411316666666668" ixy="0" ixz="0" iyx="0" iyy="0.0007843913333333333" iyz="0" izx="0" izy="0" izz="0.00024979833333333334"/>
    </inertial>
  </link>
  <gazebo reference="front_right_upper_leg">
    <material>Gazebo/Black</material>
  </gazebo>
  <joint name="motor_front_right_upper_leg" type="revolute">
    <axis xyz="0 1 0"/>
    <origin rpy="0 0 0" xyz="-0.056999999999999995 -0.03200000000000001 -0.012"/>
    <parent link="front_right_hip"/>
    <child link="front_right_upper_leg"/>
    <limit effort="4.0" lower="-1.5707963267948966" upper="2.59" velocity="4.0"/>
    <joint_properties damping="0.0" friction="0.0"/>
  </joint>
  <link name="front_right_lower_leg">
    <visual>
      <origin rpy="0 0 -1.5707963267948966" xyz="0 0 0"/>
      <geometry>
        <mesh filename="package://mini_ros/yellow_stl/RIGHT_LOWER_LEG.stl" scale="0.001 0.001 0.001"/>
      </geometry>
      <material name="black"/>
    </visual>
    <collision>
      <origin rpy="0 0 -1.5707963267948966" xyz="0 0 -0.06"/>
      <geometry>
        <box size="0.022 0.034 0.155"/>
      </geometry>
    </collision>
    <inertial>
      <mass value="0.036"/>
      <origin rpy="0 0 0" xyz="-0.01 0 -0.06"/>
      <!-- Inertial Axes -->
      <inertia ixx="7.5543e-05" ixy="0" ixz="0" iyx="0" iyy="7.352699999999999e-05" iyz="0" izx="0" izy="0" izz="4.9199999999999995e-06"/>
    </inertial>
  </link>
  <gazebo reference="front_right_lower_leg">
    <material>Gazebo/Black</material>
  </gazebo>
  <joint name="motor_front_right_lower_leg" type="revolute">
    <axis xyz="0 1 0"/>
    <origin rpy="0 0 0" xyz="0.0 -0.026499999999999996 -0.11900000000000001"/>
    <parent link="front_right_upper_leg"/>
    <child link="front_right_lower_leg"/>
    <limit effort="4.0" lower="-2.9" upper="1.5707963267948966" velocity="4.0"/>
    <joint_properties damping="0.0" friction="0.0"/>
  </joint>
  <link name="front_right_foot">
    <visual>
      <origin rpy="0 0 -1.5707963267948966" xyz="0 0 0"/>
      <geometry>
        <mesh filename="package://mini_ros/yellow_stl/FOOT.stl" scale="0.001 0.001 0.001"/>
      </geometry>
      <material name="yellow"/>
    </visual>
    <collision>
      <origin rpy="0 0 -1.5707963267948966" xyz="-0.247 0.138 0.18"/>
      <geometry>
        <mesh filename="package://mini_ros/yellow_stl/FOOT.stl" scale="0.001 0.001 0.001"/>
      </geometry>
      <contact_coefficients mu="10.1"/>
    </collision>
    <inertial>
      <mass value="0.009"/>
      <origin rpy="0 0 0" xyz="0 0 0"/>
      <!-- Inertial Axes -->
      <inertia ixx="1.74e-06" ixy="0" ixz="0" iyx="0" iyy="1.6927499999999998e-06" iyz="0" izx="0" izy="0" izz="1.4887499999999997e-06"/>
    </inertial>
  </link>
  <gazebo reference="front_right_foot">
    <kp>1000000.0</kp>
    <kd>1.0</kd>
    <mu1>0.8</mu1>
    <mu2>0.8</mu2>
    <maxVel>0.0</maxVel>
    <minDepth>0.001</minDepth>
    <material>Gazebo/Yellow</material>
  </gazebo>
   m to mm
  
  <joint name="front_right_leg_foot" type="fixed">
    <origin rpy="0 0 0" xyz="-0.0030000000000000027 0 -0.127"/>
    <parent link="front_right_lower_leg"/>
    <child link="front_right_foot"/>
  </joint>
  <link name="back_right_hip">
    <visual>
      <origin rpy="0 0 -1.5707963267948966" xyz="0 0 0"/>
      <geometry>
        <mesh filename="package://mini_ros/yellow_stl/RIGHT_HIP.stl" scale="0.001 0.001 0.001"/>
      </geometry>
      <material name="black"/>
    </visual>
    <collision>
      <origin rpy="0 0 -1.5707963267948966" xyz="0.015 -0.01 -0.01"/>
      <geometry>
        <box size="0.05 0.072 0.072"/>
      </geometry>
    </collision>
    <inertial>
      <mass value="0.209"/>
      <origin rpy="0 0 0" xyz="0 -0.075 0"/>
      <!-- Inertial Axes -->
      <inertia ixx="0.00018057599999999997" ixy="0" ixz="0" iyx="0" iyy="0.00013382966666666666" iyz="0" izx="0" izy="0" izz="0.00013382966666666666"/>
    </inertial>
  </link>
  <gazebo reference="back_right_hip">
    <material>Gazebo/Black</material>
  </gazebo>
  <joint name="motor_back_right_hip" type="revolute">
    <axis xyz="1 0 0"/>
    <origin rpy="0 0 0" xyz="-0.089 -0.038 0.03"/>
    <parent link="back_bracket"/>
    <child link="back_right_hip"/>
    <limit effort="4.0" lower="-1.04" upper="1.04" velocity="4.0"/>
    <joint_properties damping="0.0" friction="0.0"/>
  </joint>
  <link name="back_right_upper_leg">
    <visual>
      <origin rpy="0 0 -1.5707963267948966" xyz="0 0 0"/>
      <geometry>
        <mesh filename="package://mini_ros/yellow_stl/RIGHT_UPPER_LEG.stl" scale="0.001 0.001 0.001"/>
      </geometry>
      <material name="black"/>
    </visual>
    <collision>
      <origin rpy="0 0 -1.5707963267948966" xyz="0 -0.02 -0.05"/>
      <geometry>
        <box size="0.081 0.068 0.169"/>
      </geometry>
    </collision>
    <inertial>
      <mass value="0.268"/>
      <origin rpy="0 0 0" xyz="-0.005 -0.0175 -0.055"/>
      <!-- Inertial Axes -->
      <inertia ixx="0.0007411316666666668" ixy="0" ixz="0" iyx="0" iyy="0.0007843913333333333" iyz="0" izx="0" izy="0" izz="0.00024979833333333334"/>
    </inertial>
  </link>
  <gazebo reference="back_right_upper_leg">
    <material>Gazebo/Black</material>
  </gazebo>
  <joint name="motor_back_right_upper_leg" type="revolute">
    <axis xyz="0 1 0"/>
    <origin rpy="0 0 0" xyz="-0.035 -0.03200000000000001 -0.012"/>
    <parent link="back_right_hip"/>
    <child link="back_right_upper_leg"/>
    <limit effort="4.0" lower="-1.5707963267948966" upper="2.59" velocity="4.0"/>
    <joint_properties damping="0.0" friction="0.0"/>
  </joint>
  <link name="back_right_lower_leg">
    <visual>
      <origin rpy="0 0 -1.5707963267948966" xyz="0 0 0"/>
      <geometry>
        <mesh filename="package://mini_ros/yellow_stl/RIGHT_LOWER_LEG.stl" scale="0.001 0.001 0.001"/>
      </geometry>
      <material name="black"/>
    </visual>
    <collision>
      <origin rpy="0 0 -1.5707963267948966" xyz="0 0 -0.06"/>
      <geometry>
        <box size="0.022 0.034 0.155"/>
      </geometry>
    </collision>
    <inertial>
      <mass value="0.036"/>
      <origin rpy="0 0 0" xyz="-0.01 0 -0.06"/>
      <!-- Inertial Axes -->
      <inertia ixx="7.5543e-05" ixy="0" ixz="0" iyx="0" iyy="7.352699999999999e-05" iyz="0" izx="0" izy="0" izz="4.9199999999999995e-06"/>
    </inertial>
  </link>
  <gazebo reference="back_right_lower_leg">
    <material>Gazebo/Black</material>
  </gazebo>
  <joint name="motor_back_right_lower_leg" type="revolute">
    <axis xyz="0 1 0"/>
    <origin rpy="0 0 0" xyz="0.0 -0.026499999999999996 -0.11900000000000001"/>
    <parent link="back_right_upper_leg"/>
    <child link="back_right_lower_leg"/>
    <limit effort="4.0" lower="-2.9" upper="1.5707963267948966" velocity="4.0"/>
    <joint_properties damping="0.0" friction="0.0"/>
  </joint>
  <link name="back_right_foot">
    <visual>
      <origin rpy="0 0 -1.5707963267948966" xyz="0 0 0"/>
      <geometry>
        <mesh filename="package://mini_ros/yellow_stl/FOOT.stl" scale="0.001 0.001 0.001"/>
      </geometry>
      <material name="yellow"/>
    </visual>
    <collision>
      <origin rpy="0 0 -1.5707963267948966" xyz="-0.247 0.138 0.18"/>
      <geometry>
        <mesh filename="package://mini_ros/yellow_stl/FOOT.stl" scale="0.001 0.001 0.001"/>
      </geometry>
      <contact_coefficients mu="10.1"/>
    </collision>
    <inertial>
      <mass value="0.009"/>
      <origin rpy="0 0 0" xyz="0 0 0"/>
      <!-- Inertial Axes -->
      <inertia ixx="1.74e-06" ixy="0" ixz="0" iyx="0" iyy="1.6927499999999998e-06" iyz="0" izx="0" izy="0" izz="1.4887499999999997e-06"/>
    </inertial>
  </link>
  <gazebo reference="back_right_foot">
    <kp>1000000.0</kp>
    <kd>1.0</kd>
    <mu1>0.8</mu1>
    <mu2>0.8</mu2>
    <maxVel>0.0</maxVel>
    <minDepth>0.001</minDepth>
    <material>Gazebo/Yellow</material>
  </gazebo>
  <joint name="back_right_leg_foot" type="fixed">
    <origin rpy="0 0 0" xyz="-0.0030000000000000027 0 -0.127"/>
    <parent link="back_right_lower_leg"/>
    <child link="back_right_foot"/>
  </joint>
  <joint name="base_base" type="fixed">
    <origin rpy="0 0 0" xyz="0 0 0"/>
    <parent link="base_link"/>
    <child link="base_inertia"/>
  </joint>
  <joint name="base_left" type="fixed">
    <origin rpy="0 0 0" xyz="0.00 0.052 0"/>
    <parent link="base_link"/>
    <child link="chassis_left"/>
  </joint>
  <joint name="base_right" type="fixed">
    <origin rpy="0 0 0" xyz="0.00 -0.052 0"/>
    <parent link="base_link"/>
    <child link="chassis_right"/>
  </joint>
  <joint name="base_front" type="fixed">
    <origin rpy="0 0 0" xyz="0 0 0"/>
    <parent link="base_link"/>
    <child link="front"/>
  </joint>
  <joint name="base_back" type="fixed">
    <origin rpy="0 0 0" xyz="0 0 0"/>
    <parent link="base_link"/>
    <child link="back"/>
  </joint>
  <joint name="base_front_bracket" type="fixed">
    <origin rpy="0 0 0" xyz="0 0 0"/>
    <parent link="base_link"/>
    <child link="front_bracket"/>
  </joint>
  <joint name="base_back_bracket" type="fixed">
    <origin rpy="0 0 0" xyz="0 0 0"/>
    <parent link="base_link"/>
    <child link="back_bracket"/>
  </joint>
  <transmission name="front_left_hip_joint_trans">
    <type>transmission_interface/SimpleTransmission</type>
    <joint name="motor_front_left_hip">
      <hardwareInterface>hardware_interface/EffortJointInterface</hardwareInterface>
    </joint>
    <actuator name="front_left_hip_joint_motor">
      <hardwareInterface>hardware_interface/EffortJointInterface</hardwareInterface>
      <mechanicalReduction>1</mechanicalReduction>
    </actuator>
  </transmission>
  <transmission name="front_left_upper_leg_joint_trans">
    <type>transmission_interface/SimpleTransmission</type>
    <joint name="motor_front_left_lower_leg">
      <hardwareInterface>hardware_interface/EffortJointInterface</hardwareInterface>
    </joint>
    <actuator name="front_left_upper_leg_joint_motor">
      <hardwareInterface>hardware_interface/EffortJointInterface</hardwareInterface>
      <mechanicalReduction>1</mechanicalReduction>
    </actuator>
  </transmission>
  <transmission name="front_left_lower_leg_joint_trans">
    <type>transmission_interface/SimpleTransmission</type>
    <joint name="motor_front_left_upper_leg">
      <hardwareInterface>hardware_interface/EffortJointInterface</hardwareInterface>
    </joint>
    <actuator name="front_left_lower_joint_motor">
      <hardwareInterface>hardware_interface/EffortJointInterface</hardwareInterface>
      <mechanicalReduction>1</mechanicalReduction>
    </actuator>
  </transmission>
  <transmission name="front_right_hip_joint_trans">
    <type>transmission_interface/SimpleTransmission</type>
    <joint name="motor_front_right_hip">
      <hardwareInterface>hardware_interface/EffortJointInterface</hardwareInterface>
    </joint>
    <actuator name="front_right_hip_joint_motor">
      <hardwareInterface>hardware_interface/EffortJointInterface</hardwareInterface>
      <mechanicalReduction>1</mechanicalReduction>
    </actuator>
  </transmission>
  <transmission name="front_right_upper_leg_joint_trans">
    <type>transmission_interface/SimpleTransmission</type>
    <joint name="motor_front_right_lower_leg">
      <hardwareInterface>hardware_interface/EffortJointInterface</hardwareInterface>
    </joint>
    <actuator name="front_right_upper_leg_joint_motor">
      <hardwareInterface>hardware_interface/EffortJointInterface</hardwareInterface>
      <mechanicalReduction>1</mechanicalReduction>
    </actuator>
  </transmission>
  <transmission name="front_right_lower_leg_joint_trans">
    <type>transmission_interface/SimpleTransmission</type>
    <joint name="motor_front_right_upper_leg">
      <hardwareInterface>hardware_interface/EffortJointInterface</hardwareInterface>
    </joint>
    <actuator name="front_right_lower_joint_motor">
      <hardwareInterface>hardware_interface/EffortJointInterface</hardwareInterface>
      <mechanicalReduction>1</mechanicalReduction>
    </actuator>
  </transmission>
  <transmission name="back_left_hip_joint_trans">
    <type>transmission_interface/SimpleTransmission</type>
    <joint name="motor_back_left_hip">
      <hardwareInterface>hardware_interface/EffortJointInterface</hardwareInterface>
    </joint>
    <actuator name="back_left_hip_joint_motor">
      <hardwareInterface>hardware_interface/EffortJointInterface</hardwareInterface>
      <mechanicalReduction>1</mechanicalReduction>
    </actuator>
  </transmission>
  <transmission name="back_left_upper_leg_joint_trans">
    <type>transmission_interface/SimpleTransmission</type>
    <joint name="motor_back_left_lower_leg">
      <hardwareInterface>hardware_interface/EffortJointInterface</hardwareInterface>
    </joint>
    <actuator name="back_left_upper_leg_joint_motor">
      <hardwareInterface>hardware_interface/EffortJointInterface</hardwareInterface>
      <mechanicalReduction>1</mechanicalReduction>
    </actuator>
  </transmission>
  <transmission name="back_left_lower_leg_joint_trans">
    <type>transmission_interface/SimpleTransmission</type>
    <joint name="motor_back_left_upper_leg">
      <hardwareInterface>hardware_interface/EffortJointInterface</hardwareInterface>
    </joint>
    <actuator name="back_left_lower_joint_motor">
      <hardwareInterface>hardware_interface/EffortJointInterface</hardwareInterface>
      <mechanicalReduction>1</mechanicalReduction>
    </actuator>
  </transmission>
  <transmission name="back_right_hip_joint_trans">
    <type>transmission_interface/SimpleTransmission</type>
    <joint name="motor_back_right_hip">
      <hardwareInterface>hardware_interface/EffortJointInterface</hardwareInterface>
    </joint>
    <actuator name="back_right_hip_joint_motor">
      <hardwareInterface>hardware_interface/EffortJointInterface</hardwareInterface>
      <mechanicalReduction>1</mechanicalReduction>
    </actuator>
  </transmission>
  <transmission name="back_right_upper_leg_joint_trans">
    <type>transmission_interface/SimpleTransmission</type>
    <joint name="motor_back_right_lower_leg">
      <hardwareInterface>hardware_interface/EffortJointInterface</hardwareInterface>
    </joint>
    <actuator name="back_right_upper_leg_joint_motor">
      <hardwareInterface>hardware_interface/EffortJointInterface</hardwareInterface>
      <mechanicalReduction>1</mechanicalReduction>
    </actuator>
  </transmission>
  <transmission name="back_right_lower_leg_joint_trans">
    <type>transmission_interface/SimpleTransmission</type>
    <joint name="motor_back_right_upper_leg">
      <hardwareInterface>hardware_interface/EffortJointInterface</hardwareInterface>
    </joint>
    <actuator name="back_right_lower_joint_motor">
      <hardwareInterface>hardware_interface/EffortJointInterface</hardwareInterface>
      <mechanicalReduction>1</mechanicalReduction>
    </actuator>
  </transmission>
  <gazebo>
    <plugin filename="libgazebo_ros_control.so" name="gazebo_ros_control">
      <robotNamespace>/spot</robotNamespace>
    </plugin>
  </gazebo>
</robot>

